Workbook

Sheet Shift Plan GSD DE
H6: PH | CV6: PH | CY6: PH | DX6: PH | EK6: PH | EV6: PH | FF6: LPH | JW6: PH | KZ6: LPH | NB6: PH | NC6: PH
B7: ID | C7: Name | D7: Engagement | E7: Primary Role | F7: Secondary Role | G7: Team Lead | H7: 46023 | I7: 46024 | J7: 46025 | K7: 46026 | L7: 46027 | M7: 46028 | N7: 46029 | O7: 46030 | P7: 46031 | Q7: 46032 | R7: 46033 | S7: 46034 | T7: 46035 | U7: 46036 | V7: 46037 | W7: 46038 | X7: 46039 | Y7: 46040 | Z7: 46041 | AA7: 46042 | AB7: 46043 | AC7: 46044 | AD7: 46045 | AE7: 46046 | AF7: 46047 | AG7: 46048 | AH7: 46049 | AI7: 46050 | AJ7: 46051 | AK7: 46052 | AL7: 46053 | AM7: 46054 | AN7: 46055 | AO7: 46056 | AP7: 46057 | AQ7: 46058 | AR7: 46059 | AS7: 46060 | AT7: 46061 | AU7: 46062 | AV7: 46063 | AW7: 46064 | AX7: 46065 | AY7: 46066 | AZ7: 46067 | BA7: 46068 | BB7: 46069 | BC7: 46070 | BD7: 46071 | BE7: 46072 | BF7: 46073 | BG7: 46074 | BH7: 46075 | BI7: 46076 | BJ7: 46077 | BK7: 46078 | BL7: 46079 | BM7: 46080 | BN7: 46081 | BO7: 46082 | BP7: 46083 | BQ7: 46084 | BR7: 46085 | BS7: 46086 | BT7: 46087 | BU7: 46088 | BV7: 46089 | BW7: 46090 | BX7: 46091 | BY7: 46092 | BZ7: 46093 | CA7: 46094 | CB7: 46095 | CC7: 46096 | CD7: 46097 | CE7: 46098 | CF7: 46099 | CG7: 46100 | CH7: 46101 | CI7: 46102 | CJ7: 46103 | CK7: 46104 | CL7: 46105 | CM7: 46106 | CN7: 46107 | CO7: 46108 | CP7: 46109 | CQ7: 46110 | CR7: 46111 | CS7: 46112 | CT7: 46113 | CU7: 46114 | CV7: 46115 | CW7: 46116 | CX7: 46117 | CY7: 46118 | CZ7: 46119 | DA7: 46120 | DB7: 46121 | DC7: 46122 | DD7: 46123 | DE7: 46124 | DF7: 46125 | DG7: 46126 | DH7: 46127 | DI7: 46128 | DJ7: 46129 | DK7: 46130 | DL7: 46131 | DM7: 46132 | DN7: 46133 | DO7: 46134 | DP7: 46135 | DQ7: 46136 | DR7: 46137 | DS7: 46138 | DT7: 46139 | DU7: 46140 | DV7: 46141 | DW7: 46142 | DX7: 46143 | DY7: 46144 | DZ7: 46145 | EA7: 46146 | EB7: 46147 | EC7: 46148 | ED7: 46149 | EE7: 46150 | EF7: 46151 | EG7: 46152 | EH7: 46153 | EI7: 46154 | EJ7: 46155 | EK7: 46156 | EL7: 46157 | EM7: 46158 | EN7: 46159 | EO7: 46160 | EP7: 46161 | EQ7: 46162 | ER7: 46163 | ES7: 46164 | ET7: 46165 | EU7: 46166 | EV7: 46167 | EW7: 46168 | EX7: 46169 | EY7: 46170 | EZ7: 46171 | FA7: 46172 | FB7: 46173 | FC7: 46174 | FD7: 46175 | FE7: 46176 | FF7: 46177 | FG7: 46178 | FH7: 46179 | FI7: 46180 | FJ7: 46181 | FK7: 46182 | FL7: 46183 | FM7: 46184 | FN7: 46185 | FO7: 46186 | FP7: 46187 | FQ7: 46188 | FR7: 46189 | FS7: 46190 | FT7: 46191 | FU7: 46192 | FV7: 46193 | FW7: 46194 | FX7: 46195 | FY7: 46196 | FZ7: 46197 | GA7: 46198 | GB7: 46199 | GC7: 46200 | GD7: 46201 | GE7: 46202 | GF7: 46203 | GG7: 46204 | GH7: 46205 | GI7: 46206 | GJ7: 46207 | GK7: 46208 | GL7: 46209 | GM7: 46210 | GN7: 46211 | GO7: 46212 | GP7: 46213 | GQ7: 46214 | GR7: 46215 | GS7: 46216 | GT7: 46217 | GU7: 46218 | GV7: 46219 | GW7: 46220 | GX7: 46221 | GY7: 46222 | GZ7: 46223 | HA7: 46224 | HB7: 46225 | HC7: 46226 | HD7: 46227 | HE7: 46228 | HF7: 46229 | HG7: 46230 | HH7: 46231 | HI7: 46232 | HJ7: 46233 | HK7: 46234 | HL7: 46235 | HM7: 46236 | HN7: 46237 | HO7: 46238 | HP7: 46239 | HQ7: 46240 | HR7: 46241 | HS7: 46242 | HT7: 46243 | HU7: 46244 | HV7: 46245 | HW7: 46246 | HX7: 46247 | HY7: 46248 | HZ7: 46249 | IA7: 46250 | IB7: 46251 | IC7: 46252 | ID7: 46253 | IE7: 46254 | IF7: 46255 | IG7: 46256 | IH7: 46257 | II7: 46258 | IJ7: 46259 | IK7: 46260 | IL7: 46261 | IM7: 46262 | IN7: 46263 | IO7: 46264 | IP7: 46265 | IQ7: 46266 | IR7: 46267 | IS7: 46268 | IT7: 46269 | IU7: 46270 | IV7: 46271 | IW7: 46272 | IX7: 46273 | IY7: 46274 | IZ7: 46275 | JA7: 46276 | JB7: 46277 | JC7: 46278 | JD7: 46279 | JE7: 46280 | JF7: 46281 | JG7: 46282 | JH7: 46283 | JI7: 46284 | JJ7: 46285 | JK7: 46286 | JL7: 46287 | JM7: 46288 | JN7: 46289 | JO7: 46290 | JP7: 46291 | JQ7: 46292 | JR7: 46293 | JS7: 46294 | JT7: 46295 | JU7: 46296 | JV7: 46297 | JW7: 46298 | JX7: 46299 | JY7: 46300 | JZ7: 46301 | KA7: 46302 | KB7: 46303 | KC7: 46304 | KD7: 46305 | KE7: 46306 | KF7: 46307 | KG7: 46308 | KH7: 46309 | KI7: 46310 | KJ7: 46311 | KK7: 46312 | KL7: 46313 | KM7: 46314 | KN7: 46315 | KO7: 46316 | KP7: 46317 | KQ7: 46318 | KR7: 46319 | KS7: 46320 | KT7: 46321 | KU7: 46322 | KV7: 46323 | KW7: 46324 | KX7: 46325 | KY7: 46326 | KZ7: 46327 | LA7: 46328 | LB7: 46329 | LC7: 46330 | LD7: 46331 | LE7: 46332 | LF7: 46333 | LG7: 46334 | LH7: 46335 | LI7: 46336 | LJ7: 46337 | LK7: 46338 | LL7: 46339 | LM7: 46340 | LN7: 46341 | LO7: 46342 | LP7: 46343 | LQ7: 46344 | LR7: 46345 | LS7: 46346 | LT7: 46347 | LU7: 46348 | LV7: 46349 | LW7: 46350 | LX7: 46351 | LY7: 46352 | LZ7: 46353 | MA7: 46354 | MB7: 46355 | MC7: 46356 | MD7: 46357 | ME7: 46358 | MF7: 46359 | MG7: 46360 | MH7: 46361 | MI7: 46362 | MJ7: 46363 | MK7: 46364 | ML7: 46365 | MM7: 46366 | MN7: 46367 | MO7: 46368 | MP7: 46369 | MQ7: 46370 | MR7: 46371 | MS7: 46372 | MT7: 46373 | MU7: 46374 | MV7: 46375 | MW7: 46376 | MX7: 46377 | MY7: 46378 | MZ7: 46379 | NA7: 46380 | NB7: 46381 | NC7: 46382 | ND7: 46383 | NE7: 46384 | NF7: 46385 | NG7: 46386 | NH7: 46387
H8: Thursday | I8: Friday | J8: Saturday | K8: Sunday | L8: Monday | M8: Tuesday | N8: Wednesday | O8: Thursday | P8: Friday | Q8: Saturday | R8: Sunday | S8: Monday | T8: Tuesday | U8: Wednesday | V8: Thursday | W8: Friday | X8: Saturday | Y8: Sunday | Z8: Monday | AA8: Tuesday | AB8: Wednesday | AC8: Thursday | AD8: Friday | AE8: Saturday | AF8: Sunday | AG8: Monday | AH8: Tuesday | AI8: Wednesday | AJ8: Thursday | AK8: Friday | AL8: Saturday | AM8: Sunday | AN8: Monday | AO8: Tuesday | AP8: Wednesday | AQ8: Thursday | AR8: Friday | AS8: Saturday | AT8: Sunday | AU8: Monday | AV8: Tuesday | AW8: Wednesday | AX8: Thursday | AY8: Friday | AZ8: Saturday | BA8: Sunday | BB8: Monday | BC8: Tuesday | BD8: Wednesday | BE8: Thursday | BF8: Friday | BG8: Saturday | BH8: Sunday | BI8: Monday | BJ8: Tuesday | BK8: Wednesday | BL8: Thursday | BM8: Friday | BN8: Saturday | BO8: Sunday | BP8: Monday | BQ8: Tuesday | BR8: Wednesday | BS8: Thursday | BT8: Friday | BU8: Saturday | BV8: Sunday | BW8: Monday | BX8: Tuesday | BY8: Wednesday | BZ8: Thursday | CA8: Friday | CB8: Saturday | CC8: Sunday | CD8: Monday | CE8: Tuesday | CF8: Wednesday | CG8: Thursday | CH8: Friday | CI8: Saturday | CJ8: Sunday | CK8: Monday | CL8: Tuesday | CM8: Wednesday | CN8: Thursday | CO8: Friday | CP8: Saturday | CQ8: Sunday | CR8: Monday | CS8: Tuesday | CT8: Wednesday | CU8: Thursday | CV8: Friday | CW8: Saturday | CX8: Sunday | CY8: Monday | CZ8: Tuesday | DA8: Wednesday | DB8: Thursday | DC8: Friday | DD8: Saturday | DE8: Sunday | DF8: Monday | DG8: Tuesday | DH8: Wednesday | DI8: Thursday | DJ8: Friday | DK8: Saturday | DL8: Sunday | DM8: Monday | DN8: Tuesday | DO8: Wednesday | DP8: Thursday | DQ8: Friday | DR8: Saturday | DS8: Sunday | DT8: Monday | DU8: Tuesday | DV8: Wednesday | DW8: Thursday | DX8: Friday | DY8: Saturday | DZ8: Sunday | EA8: Monday | EB8: Tuesday | EC8: Wednesday | ED8: Thursday | EE8: Friday | EF8: Saturday | EG8: Sunday | EH8: Monday | EI8: Tuesday | EJ8: Wednesday | EK8: Thursday | EL8: Friday | EM8: Saturday | EN8: Sunday | EO8: Monday | EP8: Tuesday | EQ8: Wednesday | ER8: Thursday | ES8: Friday | ET8: Saturday | EU8: Sunday | EV8: Monday | EW8: Tuesday | EX8: Wednesday | EY8: Thursday | EZ8: Friday | FA8: Saturday | FB8: Sunday | FC8: Monday | FD8: Tuesday | FE8: Wednesday | FF8: Thursday | FG8: Friday | FH8: Saturday | FI8: Sunday | FJ8: Monday | FK8: Tuesday | FL8: Wednesday | FM8: Thursday | FN8: Friday | FO8: Saturday | FP8: Sunday | FQ8: Monday | FR8: Tuesday | FS8: Wednesday | FT8: Thursday | FU8: Friday | FV8: Saturday | FW8: Sunday | FX8: Monday | FY8: Tuesday | FZ8: Wednesday | GA8: Thursday | GB8: Friday | GC8: Saturday | GD8: Sunday | GE8: Monday | GF8: Tuesday | GG8: Wednesday | GH8: Thursday | GI8: Friday | GJ8: Saturday | GK8: Sunday | GL8: Monday | GM8: Tuesday | GN8: Wednesday | GO8: Thursday | GP8: Friday | GQ8: Saturday | GR8: Sunday | GS8: Monday | GT8: Tuesday | GU8: Wednesday | GV8: Thursday | GW8: Friday | GX8: Saturday | GY8: Sunday | GZ8: Monday | HA8: Tuesday | HB8: Wednesday | HC8: Thursday | HD8: Friday | HE8: Saturday | HF8: Sunday | HG8: Monday | HH8: Tuesday | HI8: Wednesday | HJ8: Thursday | HK8: Friday | HL8: Saturday | HM8: Sunday | HN8: Monday | HO8: Tuesday | HP8: Wednesday | HQ8: Thursday | HR8: Friday | HS8: Saturday | HT8: Sunday | HU8: Monday | HV8: Tuesday | HW8: Wednesday | HX8: Thursday | HY8: Friday | HZ8: Saturday | IA8: Sunday | IB8: Monday | IC8: Tuesday | ID8: Wednesday | IE8: Thursday | IF8: Friday | IG8: Saturday | IH8: Sunday | II8: Monday | IJ8: Tuesday | IK8: Wednesday | IL8: Thursday | IM8: Friday | IN8: Saturday | IO8: Sunday | IP8: Monday | IQ8: Tuesday | IR8: Wednesday | IS8: Thursday | IT8: Friday | IU8: Saturday | IV8: Sunday | IW8: Monday | IX8: Tuesday | IY8: Wednesday | IZ8: Thursday | JA8: Friday | JB8: Saturday | JC8: Sunday | JD8: Monday | JE8: Tuesday | JF8: Wednesday | JG8: Thursday | JH8: Friday | JI8: Saturday | JJ8: Sunday | JK8: Monday | JL8: Tuesday | JM8: Wednesday | JN8: Thursday | JO8: Friday | JP8: Saturday | JQ8: Sunday | JR8: Monday | JS8: Tuesday | JT8: Wednesday | JU8: Thursday | JV8: Friday | JW8: Saturday | JX8: Sunday | JY8: Monday | JZ8: Tuesday | KA8: Wednesday | KB8: Thursday | KC8: Friday | KD8: Saturday | KE8: Sunday | KF8: Monday | KG8: Tuesday | KH8: Wednesday | KI8: Thursday | KJ8: Friday | KK8: Saturday | KL8: Sunday | KM8: Monday | KN8: Tuesday | KO8: Wednesday | KP8: Thursday | KQ8: Friday | KR8: Saturday | KS8: Sunday | KT8: Monday | KU8: Tuesday | KV8: Wednesday | KW8: Thursday | KX8: Friday | KY8: Saturday | KZ8: Sunday | LA8: Monday | LB8: Tuesday | LC8: Wednesday | LD8: Thursday | LE8: Friday | LF8: Saturday | LG8: Sunday | LH8: Monday | LI8: Tuesday | LJ8: Wednesday | LK8: Thursday | LL8: Friday | LM8: Saturday | LN8: Sunday | LO8: Monday | LP8: Tuesday | LQ8: Wednesday | LR8: Thursday | LS8: Friday | LT8: Saturday | LU8: Sunday | LV8: Monday | LW8: Tuesday | LX8: Wednesday | LY8: Thursday | LZ8: Friday | MA8: Saturday | MB8: Sunday | MC8: Monday | MD8: Tuesday | ME8: Wednesday | MF8: Thursday | MG8: Friday | MH8: Saturday | MI8: Sunday | MJ8: Monday | MK8: Tuesday | ML8: Wednesday | MM8: Thursday | MN8: Friday | MO8: Saturday | MP8: Sunday | MQ8: Monday | MR8: Tuesday | MS8: Wednesday | MT8: Thursday | MU8: Friday | MV8: Saturday | MW8: Sunday | MX8: Monday | MY8: Tuesday | MZ8: Wednesday | NA8: Thursday | NB8: Friday | NC8: Saturday | ND8: Sunday | NE8: Monday | NF8: Tuesday | NG8: Wednesday | NH8: Thursday
A9: 1 | B9: 9074584 | C9: Teresa Kwasniewska | D9: Full Time | E9: Voice | F9: Voice | G9: Jaroslaw Brzeszkiewicz | H9: PH | I9: 06:00 - 15:00 | J9: OFFWE | K9: OFFWE | L9: 06:00 - 15:00 | M9: 06:00 - 15:00 | N9: 06:00 - 15:00 | O9: 06:00 - 15:00 | P9: 06:00 - 15:00 | Q9: OFFWE | R9: OFFWE | S9: 06:00 - 15:00 | T9: 06:00 - 15:00 | U9: 06:00 - 15:00 | V9: 06:00 - 15:00 | W9: AL | X9: OFFWE | Y9: OFFWE | Z9: AL | AA9: AL | AB9: AL | AC9: AL | AD9: AL | AE9: OFFWE | AF9: OFFWE | AG9: AL | AH9: 06:00 - 15:00 | AI9: 06:00 - 15:00 | AJ9: 06:00 - 15:00 | AK9: 06:00 - 15:00 | AL9: OFFWE | AM9: OFFWE | AN9: 06:00 - 15:00 | AO9: 06:00 - 15:00 | AP9: 06:00 - 15:00 | AQ9: 06:00 - 15:00 | AR9: 06:00 - 15:00 | AS9: OFFWE | AT9: OFFWE | AU9: 06:00 - 15:00 | AV9: 06:00 - 15:00 | AW9: 06:00 - 15:00 | AX9: HSL * | AY9: SL | AZ9: OFFWE | BA9: OFFWE | BB9: 06:00 - 15:00 | BC9: 06:00 - 15:00 | BD9: 06:00 - 15:00 | BE9: 06:00 - 15:00 | BF9: 06:00 - 15:00 | BG9: OFFWE | BH9: OFFWE | BI9: 06:00 - 15:00 | BJ9: 06:00 - 15:00 | BK9: 06:00 - 15:00 | BL9: 06:00 - 15:00 | BM9: 06:00 - 15:00 | BN9: OFFWE | BO9: OFFWE | BP9: 06:00 - 15:00 | BQ9: 06:00 - 15:00 | BR9: 06:00 - 15:00 | BS9: 06:00 - 15:00 | BT9: 06:00 - 15:00 | BU9: OFFWE | BV9: OFFWE | BW9: 06:00 - 15:00 | BX9: 06:00 - 15:00 | BY9: 06:00 - 15:00 | BZ9: 06:00 - 15:00 | CA9: 06:00 - 15:00 | CB9: OFFWE | CC9: OFFWE | CD9: 06:00 - 15:00 | CE9: 06:00 - 15:00 | CF9: 06:00 - 15:00 | CG9: 06:00 - 15:00 | CH9: 06:00 - 15:00 | CI9: OFFWE | CJ9: OFFWE | CK9: 06:00 - 15:00 | CL9: 06:00 - 15:00 | CM9: 06:00 - 15:00 | CN9: 06:00 - 15:00 | CO9: 06:00 - 15:00 | CP9: OFFWE | CQ9: OFFWE | CR9: 06:00 - 15:00 | CS9: 06:00 - 15:00 | CT9: 06:00 - 15:00 | CU9: 06:00 - 15:00 | CV9: PH | CW9: OFFWE | CX9: OFFWE | CY9: PH | CZ9: 06:00 - 15:00 | DA9: 06:00 - 15:00 | DB9: 06:00 - 15:00 | DC9: 06:00 - 15:00 | DD9: OFFWE | DE9: OFFWE | DF9: AL | DG9: AL | DH9: AL | DI9: AL | DJ9: AL | DK9: OFFWE | DL9: OFFWE | DM9: 06:00 - 15:00 | DN9: 06:00 - 15:00 | DO9: 06:00 - 15:00 | DP9: 06:00 - 15:00 | DQ9: 06:00 - 15:00 | DR9: OFFWE | DS9: OFFWE | DT9: 06:00 - 15:00 | DU9: 06:00 - 15:00 | DV9: 06:00 - 15:00 | DW9: 06:00 - 15:00 | DX9: PH | DY9: OFFWE | DZ9: OFFWE | EA9: 06:00 - 15:00 | EB9: 06:00 - 15:00 | EC9: 06:00 - 15:00 | ED9: 06:00 - 15:00 | EE9: 06:00 - 15:00 | EF9: OFFWE | EG9: OFFWE | EH9: SL | EI9: SL | EJ9: 06:00 - 15:00 | EK9: PH | EL9: 06:00 - 15:00 | EM9: OFFWE | EN9: OFFWE | EO9: 06:00 - 15:00 | EP9: 06:00 - 15:00 | EQ9: 06:00 - 15:00 | ER9: 06:00 - 15:00 | ES9: 06:00 - 15:00 | ET9: OFFWE | EU9: OFFWE | EV9: PH | EW9: 06:00 - 15:00 | EX9: 06:00 - 15:00 | EY9: 06:00 - 15:00 | EZ9: 06:00 - 15:00 | FA9: OFFWE | FB9: OFFWE | FC9: 06:00 - 15:00 | FD9: 06:00 - 15:00 | FE9: 06:00 - 15:00 | FF9: LPH | FG9: 06:00 - 15:00 | FH9: OFFWE | FI9: OFFWE
A10: 2 | B10: 9074334 | C10: Aleksandrina Dencheva | D10: Full Time | E10: Voice | F10: Voice | G10: Delia Panaitescu | H10: PH | I10: OFF | J10: 22:00 - 07:00 | K10: 22:00 - 07:00 | L10: 22:00 - 07:00 | M10: 22:00 - 07:00 | N10: 22:00 - 07:00 | O10: OFF | P10: OFF | Q10: 13:00 - 22:00 | R10: 13:00 - 22:00 | S10: OFF | T10: OFF | U10: 10:00 - 19:00 | V10: 10:00 - 19:00 | W10: 10:00 - 19:00 | X10: 13:00 - 22:00 | Y10: 13:00 - 22:00 | Z10: OFF | AA10: OFF | AB10: 10:00 - 19:00 | AC10: 22:00 - 07:00 | AD10: 22:00 - 07:00 | AE10: 22:00 - 07:00 | AF10: 22:00 - 07:00 | AG10: OFF | AH10: 10:00 - 19:00 | AI10: 10:00 - 19:00 | AJ10: 10:00 - 19:00 | AK10: 10:00 - 19:00 | AL10: OFFWE | AM10: 13:00 - 22:00 | AN10: 10:00 - 19:00 | AO10: 10:00 - 19:00 | AP10: 10:00 - 19:00 | AQ10: OFF | AR10: OFF | AS10: 13:00 - 22:00 | AT10: 13:00 - 22:00 | AU10: 22:00 - 07:00 | AV10: 22:00 - 07:00 | AW10: 22:00 - 07:00 | AX10: OFF | AY10: OFF | AZ10: 13:00 - 22:00 | BA10: 13:00 - 22:00 | BB10: 10:00 - 19:00 | BC10: 10:00 - 19:00 | BD10: 10:00 - 19:00 | BE10: OFF | BF10: 08:00 - 17:00 | BG10: 13:00 - 22:00 | BH10: OFFWE | BI10: OFF | BJ10: 10:00 - 19:00 | BK10: 10:00 - 19:00 | BL10: OFF | BM10: 22:00 - 07:00 | BN10: 22:00 - 07:00 | BO10: 22:00 - 07:00 | BP10: 22:00 - 07:00 | BQ10: 22:00 - 07:00 | BR10: OFF | BS10: 08:00 - 17:00 | BT10: 08:00 - 17:00 | BU10: 13:00 - 22:00 | BV10: OFFWE | BW10: 08:00 - 17:00 | BX10: 08:00 - 17:00 | BY10: 08:00 - 17:00 | BZ10: OFF | CA10: OFF | CB10: 13:00 - 22:00 | CC10: 13:00 - 22:00 | CD10: 22:00 - 07:00 | CE10: 22:00 - 07:00 | CF10: 22:00 - 07:00 | CG10: OFF | CH10: SL | CI10: 13:00 - 22:00 | CJ10: OFFWE | CK10: 13:00 - 22:00 | CL10: 13:00 - 22:00 | CM10: 13:00 - 22:00 | CN10: 13:00 - 22:00 | CO10: OFF | CP10: OFFWE | CQ10: 13:00 - 22:00 | CR10: OFF | CS10: 22:00 - 07:00 | CT10: 22:00 - 07:00 | CU10: 22:00 - 07:00 | CV10: 22:00 - 07:00 | CW10: 22:00 - 07:00 | CX10: OFFWE | CY10: PH | CZ10: 08:00 - 17:00 | DA10: 08:00 - 17:00 | DB10: 08:00 - 17:00 | DC10: OFF | DD10: 13:00 - 22:00 | DE10: 13:00 - 22:00 | DF10: 22:00 - 07:00 | DG10: 22:00 - 07:00 | DH10: 22:00 - 07:00 | DI10: OFF | DJ10: OFF | DK10: 13:00 - 22:00 | DL10: 13:00 - 22:00 | DM10: CD | DN10: 08:00 - 17:00 | DO10: 08:00 - 17:00 | DP10: OFF | DQ10: OFF | DR10: 13:00 - 22:00 | DS10: 13:00 - 22:00 | DT10: 22:00 - 07:00 | DU10: 22:00 - 07:00 | DV10: 22:00 - 07:00 | DW10: OFF | DX10: PH | DY10: 13:00 - 22:00 | DZ10: 13:00 - 22:00 | EA10: OFF | EB10: 08:00 - 17:00 | EC10: 08:00 - 17:00 | ED10: 08:00 - 17:00 | EE10: 08:00 - 17:00 | EF10: OFF | EG10: 13:00 - 22:00 | EH10: 06:00 - 15:00 | EI10: 06:00 - 15:00 | EJ10: 06:00 - 15:00 | EK10: 13:00 - 22:00 | EL10: OFF | EM10: 22:00 - 07:00 | EN10: 22:00 - 07:00 | EO10: 22:00 - 07:00 | EP10: 22:00 - 07:00 | EQ10: 22:00 - 07:00 | ER10: OFF | ES10: 08:00 - 17:00 | ET10: OFFWE | EU10: OFFWE | EV10: PH | EW10: OFF | EX10: 08:00 - 17:00 | EY10: 08:00 - 17:00 | EZ10: 08:00 - 17:00 | FA10: 13:00 - 22:00 | FB10: 13:00 - 22:00 | FC10: OFF | FD10: 07:00 - 16:00 | FE10: 07:00 - 16:00 | FF10: LPH | FG10: 22:00 - 07:00 | FH10: 22:00 - 07:00 | FI10: 22:00 - 07:00 | FJ10: 22:00 - 07:00 | FK10: 22:00 - 07:00 | GA10: 22:00 - 07:00 | GB10: 22:00 - 07:00 | GC10: 22:00 - 07:00 | GD10: 22:00 - 07:00 | GE10: 22:00 - 07:00
A11: 3 | B11: 9074375 | C11: Elena Schlosser | D11: Full Time | E11: Voice | F11: Voice | G11: Karlo Coric | H11: PH | I11: 07:00 - 16:00 | J11: 07:00 - 16:00 | K11: 07:00 - 16:00 | L11: 07:00 - 16:00 | M11: 07:00 - 16:00 | N11: OFF | O11: OFF | P11: 07:00 - 16:00 | Q11: 07:00 - 16:00 | R11: OFFWE | S11: HAL * | T11: 07:00 - 16:00 | U11: OFF | V11: 07:00 - 16:00 | W11: 07:00 - 16:00 | X11: 07:00 - 16:00 | Y11: OFFWE | Z11: 07:00 - 16:00 | AA11: 07:00 - 16:00 | AB11: OFF | AC11: 07:00 - 16:00 | AD11: 07:00 - 16:00 | AE11: 07:00 - 16:00 | AF11: OFFWE | AG11: 07:00 - 16:00 | AH11: 07:00 - 16:00 | AI11: OFF | AJ11: 07:00 - 16:00 | AK11: 07:00 - 16:00 | AL11: 07:00 - 16:00 | AM11: OFFWE | AN11: 07:00 - 16:00 | AO11: 07:00 - 16:00 | AP11: OFF | AQ11: 07:00 - 16:00 | AR11: 07:00 - 16:00 | AS11: 07:00 - 16:00 | AT11: OFFWE | AU11: 07:00 - 16:00 | AV11: 07:00 - 16:00 | AW11: OFF | AX11: 07:00 - 16:00 | AY11: 07:00 - 16:00 | AZ11: 07:00 - 16:00 | BA11: OFFWE | BB11: 07:00 - 16:00 | BC11: 07:00 - 16:00 | BD11: OFF | BE11: 07:00 - 16:00 | BF11: 07:00 - 16:00 | BG11: 07:00 - 16:00 | BH11: OFFWE | BI11: 07:00 - 16:00 | BJ11: 07:00 - 16:00 | BK11: OFF | BL11: 07:00 - 16:00 | BM11: 07:00 - 16:00 | BN11: 07:00 - 16:00 | BO11: OFFWE | BP11: 07:00 - 16:00 | BQ11: 07:00 - 16:00 | BR11: OFF | BS11: 07:00 - 16:00 | BT11: 07:00 - 16:00 | BU11: 07:00 - 16:00 | BV11: OFFWE | BW11: 07:00 - 16:00 | BX11: 07:00 - 16:00 | BY11: OFF | BZ11: 07:00 - 16:00 | CA11: 07:00 - 16:00 | CB11: 07:00 - 16:00 | CC11: OFFWE | CD11: 07:00 - 16:00 | CE11: 07:00 - 16:00 | CF11: OFF | CG11: 07:00 - 16:00 | CH11: 07:00 - 16:00 | CI11: 07:00 - 16:00 | CJ11: OFFWE | CK11: 07:00 - 16:00 | CL11: HAL * | CM11: OFF | CN11: 07:00 - 16:00 | CO11: 07:00 - 16:00 | CP11: 07:00 - 16:00 | CQ11: OFFWE | CR11: 07:00 - 16:00 | CS11: 07:00 - 16:00 | CT11: OFF | CU11: 07:00 - 16:00 | CV11: 07:00 - 16:00 | CW11: 07:00 - 16:00 | CX11: OFFWE | CY11: 07:00 - 16:00 | CZ11: 07:00 - 16:00 | DA11: OFF | DB11: 07:00 - 16:00 | DC11: 07:00 - 16:00 | DD11: 07:00 - 16:00 | DE11: OFFWE | DF11: 07:00 - 16:00 | DG11: 07:00 - 16:00 | DH11: OFF | DI11: 07:00 - 16:00 | DJ11: 07:00 - 16:00 | DK11: 07:00 - 16:00 | DL11: OFFWE | DM11: AL | DN11: AL | DO11: OFF | DP11: CD | DQ11: AL | DR11: OFFWE | DS11: OFFWE | DT11: AL | DU11: CD | DV11: OFF | DW11: 07:00 - 16:00 | DX11: 07:00 - 16:00 | DY11: OFFWE | DZ11: OFFWE | EA11: 07:00 - 16:00 | EB11: 07:00 - 16:00 | EC11: 07:00 - 16:00 | ED11: OFF | EE11: OFF | EF11: 07:00 - 16:00 | EG11: 07:00 - 16:00 | EH11: OFF | EI11: 07:00 - 16:00 | EJ11: 07:00 - 16:00 | EK11: 07:00 - 16:00 | EL11: CD | EM11: 07:00 - 16:00 | EN11: OFF | EO11: 07:00 - 16:00 | EP11: 07:00 - 16:00 | EQ11: 07:00 - 16:00 | ER11: OFF | ES11: OFF | ET11: 07:00 - 16:00 | EU11: 07:00 - 16:00 | EV11: PH | EW11: 07:00 - 16:00 | EX11: 07:00 - 16:00 | EY11: 07:00 - 16:00 | EZ11: 07:00 - 16:00 | FA11: 07:00 - 16:00 | FB11: OFFWE | FC11: 07:00 - 16:00 | FD11: 07:00 - 16:00 | FE11: OFF | FF11: LPH | FG11: 07:00 - 16:00 | FH11: 07:00 - 16:00 | FI11: 07:00 - 16:00
A12: 4 | B12: 9074535 | C12: Lubomir Stoyanov | D12: Full Time | E12: Voice | F12: Voice | G12: Delia Panaitescu | H12: 22:00 - 07:00 | I12: 22:00 - 07:00 | J12: OFFWE | K12: OFFWE | L12: 06:00 - 15:00 | M12: CD | N12: CD | O12: 22:00 - 07:00 | P12: 22:00 - 07:00 | Q12: 22:00 - 07:00 | R12: 22:00 - 07:00 | S12: CD | T12: 06:00 - 15:00 | U12: 06:00 - 15:00 | V12: 06:00 - 15:00 | W12: 06:00 - 15:00 | X12: OFFWE | Y12: OFFWE | Z12: 06:00 - 15:00 | AA12: 06:00 - 15:00 | AB12: 06:00 - 15:00 | AC12: 06:00 - 15:00 | AD12: 06:00 - 15:00 | AE12: OFFWE | AF12: OFFWE | AG12: 22:00 - 07:00 | AH12: 22:00 - 07:00 | AI12: 22:00 - 07:00 | AJ12: 22:00 - 07:00 | AK12: 22:00 - 07:00 | AL12: OFFWE | AM12: OFFWE | AN12: 06:00 - 15:00 | AO12: AL | AP12: 07:00 - 16:00 | AQ12: 06:00 - 15:00 | AR12: AL | AS12: OFFWE | AT12: OFFWE | AU12: 06:00 - 15:00 | AV12: AL | AW12: 06:00 - 15:00 | AX12: 06:00 - 15:00 | AY12: 06:00 - 15:00 | AZ12: OFFWE | BA12: OFFWE | BB12: OFF | BC12: AL | BD12: 22:00 - 07:00 | BE12: 22:00 - 07:00 | BF12: 22:00 - 07:00 | BG12: 22:00 - 07:00 | BH12: 22:00 - 07:00 | BI12: OFF | BJ12: AL | BK12: 06:00 - 15:00 | BL12: 06:00 - 15:00 | BM12: 06:00 - 15:00 | BN12: OFFWE | BO12: OFFWE | BP12: 06:00 - 15:00 | BQ12: AL | BR12: 06:00 - 15:00 | BS12: 06:00 - 15:00 | BT12: 06:00 - 15:00 | BU12: OFFWE | BV12: 07:00 - 16:00 | BW12: OFF | BX12: AL | BY12: 22:00 - 07:00 | BZ12: 22:00 - 07:00 | CA12: 22:00 - 07:00 | CB12: 22:00 - 07:00 | CC12: OFFWE | CD12: OFF | CE12: AL | CF12: 06:00 - 15:00 | CG12: 06:00 - 15:00 | CH12: OFF | CI12: OFFWE | CJ12: 07:00 - 16:00 | CK12: 06:00 - 15:00 | CL12: AL | CM12: 06:00 - 15:00 | CN12: OFF | CO12: 06:00 - 15:00 | CP12: 22:00 - 07:00 | CQ12: 22:00 - 07:00 | CR12: 22:00 - 07:00 | CS12: AL | CT12: 06:00 - 15:00 | CU12: 06:00 - 15:00 | CV12: PH | CW12: OFFWE | CX12: 07:00 - 16:00 | CY12: 22:00 - 07:00 | CZ12: AL | DA12: 07:00 - 16:00 | DB12: OFF | DC12: 06:00 - 15:00 | DD12: 22:00 - 07:00 | DE12: 22:00 - 07:00 | DF12: CD | DG12: AL | DH12: 06:00 - 15:00 | DI12: 22:00 - 07:00 | DJ12: 22:00 - 07:00 | DK12: OFFWE | DL12: OFFWE | DM12: 06:00 - 15:00 | DN12: OFF | DO12: OFF | DP12: 06:00 - 15:00 | DQ12: 22:00 - 07:00 | DR12: 22:00 - 07:00 | DS12: 22:00 - 07:00 | DT12: OFF | DU12: SL | DV12: 07:00 - 16:00 | DW12: 06:00 - 15:00 | DX12: 22:00 - 07:00 | DY12: 22:00 - 07:00 | DZ12: OFFWE | EA12: 06:00 - 15:00 | EB12: 06:00 - 15:00 | EC12: 06:00 - 15:00 | ED12: 06:00 - 15:00 | EE12: 06:00 - 15:00 | EF12: OFFWE | EG12: OFFWE | EH12: 22:00 - 07:00 | EI12: 22:00 - 07:00 | EJ12: 22:00 - 07:00 | EK12: 22:00 - 07:00 | EL12: 22:00 - 07:00 | EM12: OFFWE | EN12: OFFWE | EO12: 06:00 - 15:00 | EP12: 06:00 - 15:00 | EQ12: 06:00 - 15:00 | ER12: 06:00 - 15:00 | ES12: 06:00 - 15:00 | ET12: OFFWE | EU12: OFFWE | EV12: PH | EW12: OFF | EX12: 22:00 - 07:00 | EY12: 22:00 - 07:00 | EZ12: 22:00 - 07:00 | FA12: 22:00 - 07:00 | FB12: 22:00 - 07:00 | FC12: OFF | FD12: 06:00 - 15:00 | FE12: 06:00 - 15:00 | FF12: 06:00 - 15:00 | FG12: 06:00 - 15:00 | FH12: OFFWE | FI12: OFFWE | FJ12: AL | FK12: AL | FL12: AL | FM12: AL | FQ12: 22:00 - 07:00 | FR12: 22:00 - 07:00 | FS12: 22:00 - 07:00 | FT12: 22:00 - 07:00 | FU12: 22:00 - 07:00 | IB12: AL | IC12: AL | ID12: AL | IE12: AL | IF12: AL | II12: AL
A13: 5 | B13: 9074356 | C13: Christian Koch | D13: Full Time | E13: Voice | F13: Voice | G13: Tobias Rossberg | H13: 13:00 - 22:00 | I13: CD | J13: OFFWE | K13: OFFWE | L13: 13:00 - 22:00 | M13: 13:00 - 22:00 | N13: 13:00 - 22:00 | O13: 13:00 - 22:00 | P13: CD | Q13: OFFWE | R13: OFFWE | S13: 13:00 - 22:00 | T13: 13:00 - 22:00 | U13: 13:00 - 22:00 | V13: 13:00 - 22:00 | W13: 13:00 - 22:00 | X13: OFFWE | Y13: OFFWE | Z13: 13:00 - 22:00 | AA13: 13:00 - 22:00 | AB13: 13:00 - 22:00 | AC13: 13:00 - 22:00 | AD13: 13:00 - 22:00 | AE13: OFFWE | AF13: OFFWE | AG13: CD | AH13: 13:00 - 22:00 | AI13: 13:00 - 22:00 | AJ13: 13:00 - 22:00 | AK13: 13:00 - 22:00 | AL13: OFFWE | AM13: OFFWE | AN13: 13:00 - 22:00 | AO13: 13:00 - 22:00 | AP13: 13:00 - 22:00 | AQ13: 13:00 - 22:00 | AR13: 13:00 - 22:00 | AS13: OFFWE | AT13: OFFWE | AU13: 13:00 - 22:00 | AV13: 13:00 - 22:00 | AW13: 13:00 - 22:00 | AX13: 13:00 - 22:00 | AY13: 13:00 - 22:00 | AZ13: OFFWE | BA13: OFFWE | BB13: 13:00 - 22:00 | BC13: 13:00 - 22:00 | BD13: 13:00 - 22:00 | BE13: 13:00 - 22:00 | BF13: 13:00 - 22:00 | BG13: OFFWE | BH13: OFFWE | BI13: 13:00 - 22:00 | BJ13: 13:00 - 22:00 | BK13: 13:00 - 22:00 | BL13: 13:00 - 22:00 | BM13: 13:00 - 22:00 | BN13: OFFWE | BO13: OFFWE | BP13: 13:00 - 22:00 | BQ13: 13:00 - 22:00 | BR13: 13:00 - 22:00 | BS13: 13:00 - 22:00 | BT13: 13:00 - 22:00 | BU13: OFFWE | BV13: OFFWE | BW13: SL | BX13: SL | BY13: SL | BZ13: SL | CA13: SL | CB13: OFFWE | CC13: OFFWE | CD13: 13:00 - 22:00 | CE13: 13:00 - 22:00 | CF13: 13:00 - 22:00 | CG13: 13:00 - 22:00 | CH13: 13:00 - 22:00 | CI13: OFFWE | CJ13: OFFWE | CK13: AL | CL13: AL | CM13: AL | CN13: AL | CO13: AL | CP13: OFFWE | CQ13: OFFWE | CR13: 13:00 - 22:00 | CS13: 13:00 - 22:00 | CT13: 13:00 - 22:00 | CU13: 13:00 - 22:00 | CV13: 13:00 - 22:00 | CW13: OFFWE | CX13: OFFWE | CY13: 13:00 - 22:00 | CZ13: 13:00 - 22:00 | DA13: 13:00 - 22:00 | DB13: 13:00 - 22:00 | DC13: 13:00 - 22:00 | DD13: OFFWE | DE13: OFFWE | DF13: 13:00 - 22:00 | DG13: 13:00 - 22:00 | DH13: 13:00 - 22:00 | DI13: 13:00 - 22:00 | DJ13: 13:00 - 22:00 | DK13: OFFWE | DL13: OFFWE | DM13: CD | DN13: 13:00 - 22:00 | DO13: 13:00 - 22:00 | DP13: 13:00 - 22:00 | DQ13: 13:00 - 22:00 | DR13: OFFWE | DS13: OFFWE | DT13: CD | DU13: 13:00 - 22:00 | DV13: 13:00 - 22:00 | DW13: 13:00 - 22:00 | DX13: 13:00 - 22:00 | DY13: OFFWE | DZ13: OFFWE | EA13: 13:00 - 22:00 | EB13: 13:00 - 22:00 | EC13: 13:00 - 22:00 | ED13: 13:00 - 22:00 | EE13: 13:00 - 22:00 | EF13: OFFWE | EG13: OFFWE | EH13: 13:00 - 22:00 | EI13: 13:00 - 22:00 | EJ13: 13:00 - 22:00 | EK13: PH | EL13: 13:00 - 22:00 | EM13: OFFWE | EN13: OFFWE | EO13: AL | EP13: OL | EQ13: 13:00 - 22:00 | ER13: 13:00 - 22:00 | ES13: 13:00 - 22:00 | ET13: OFFWE | EU13: OFFWE | EV13: 13:00 - 22:00 | EW13: CD | EX13: 13:00 - 22:00 | EY13: 13:00 - 22:00 | EZ13: 13:00 - 22:00 | FA13: OFFWE | FB13: OFFWE | FC13: 13:00 - 22:00 | FD13: 13:00 - 22:00 | FE13: 13:00 - 22:00 | FF13: 13:00 - 22:00 | FG13: 13:00 - 22:00 | FH13: OFFWE | FI13: OFFWE | FM13: SL | GI13: AL | GJ13: OFFWE | GK13: OFFWE | GL13: AL | GM13: AL | GN13: AL | GO13: AL | GP13: AL | GQ13: OFFWE | GR13: OFFWE | GS13: AL | GT13: AL | GU13: AL | GV13: AL | GW13: AL | GX13: OFFWE | GY13: OFFWE | JY13: AL | JZ13: AL | KA13: AL | KB13: AL | KC13: AL | MJ13: AL | MK13: AL | ML13: AL | MM13: AL | MN13: AL
A14: 6 | B14: 9074563 | C14: Ralf Turski | D14: Full Time | E14: Voice | F14: Voice | G14: Karlo Coric | H14: PH | I14: 08:00 - 17:00 | J14: OFFWE | K14: OFFWE | L14: 08:00 - 17:00 | M14: 08:00 - 17:00 | N14: 08:00 - 17:00 | O14: 08:00 - 17:00 | P14: 08:00 - 17:00 | Q14: OFFWE | R14: OFFWE | S14: 08:00 - 17:00 | T14: 08:00 - 17:00 | U14: 08:00 - 17:00 | V14: 08:00 - 17:00 | W14: 08:00 - 17:00 | X14: OFFWE | Y14: OFFWE | Z14: 08:00 - 17:00 | AA14: SL | AB14: 08:00 - 17:00 | AC14: HSL * | AD14: SL | AE14: OFFWE | AF14: OFFWE | AG14: SL | AH14: SL | AI14: SL | AJ14: SL | AK14: SL | AL14: OFFWE | AM14: OFFWE | AN14: 08:00 - 17:00 | AO14: 08:00 - 17:00 | AP14: 08:00 - 17:00 | AQ14: 08:00 - 17:00 | AR14: 08:00 - 17:00 | AS14: OFFWE | AT14: OFFWE | AU14: 08:00 - 17:00 | AV14: 08:00 - 17:00 | AW14: 08:00 - 17:00 | AX14: 08:00 - 17:00 | AY14: 08:00 - 17:00 | AZ14: OFFWE | BA14: OFFWE | BB14: 08:00 - 17:00 | BC14: 08:00 - 17:00 | BD14: 08:00 - 17:00 | BE14: 08:00 - 17:00 | BF14: 08:00 - 17:00 | BG14: OFFWE | BH14: OFFWE | BI14: AL | BJ14: AL | BK14: AL | BL14: AL | BM14: AL | BN14: OFFWE | BO14: OFFWE | BP14: 08:00 - 17:00 | BQ14: 08:00 - 17:00 | BR14: 08:00 - 17:00 | BS14: 08:00 - 17:00 | BT14: 08:00 - 17:00 | BU14: OFFWE | BV14: OFFWE | BW14: 08:00 - 17:00 | BX14: 08:00 - 17:00 | BY14: 08:00 - 17:00 | BZ14: 08:00 - 17:00 | CA14: 08:00 - 17:00 | CB14: OFFWE | CC14: OFFWE | CD14: 08:00 - 17:00 | CE14: 08:00 - 17:00 | CF14: 08:00 - 17:00 | CG14: 08:00 - 17:00 | CH14: 08:00 - 17:00 | CI14: OFFWE | CJ14: OFFWE | CK14: 08:00 - 17:00 | CL14: 08:00 - 17:00 | CM14: 08:00 - 17:00 | CN14: 08:00 - 17:00 | CO14: 08:00 - 17:00 | CP14: OFFWE | CQ14: OFFWE | CR14: AL | CS14: AL | CT14: AL | CU14: AL | CV14: PH | CW14: OFFWE | CX14: OFFWE | CY14: PH | CZ14: AL | DA14: AL | DB14: AL | DC14: AL | DD14: OFFWE | DE14: OFFWE | DF14: 08:00 - 17:00 | DG14: 08:00 - 17:00 | DH14: 08:00 - 17:00 | DI14: 08:00 - 17:00 | DJ14: 08:00 - 17:00 | DK14: OFFWE | DL14: OFFWE | DM14: 08:00 - 17:00 | DN14: 08:00 - 17:00 | DO14: 08:00 - 17:00 | DP14: 08:00 - 17:00 | DQ14: 08:00 - 17:00 | DR14: OFFWE | DS14: OFFWE | DT14: AL | DU14: 08:00 - 17:00 | DV14: 08:00 - 17:00 | DW14: 08:00 - 17:00 | DX14: PH | DY14: OFFWE | DZ14: OFFWE | EA14: 08:00 - 17:00 | EB14: 08:00 - 17:00 | EC14: 08:00 - 17:00 | ED14: 08:00 - 17:00 | EE14: 08:00 - 17:00 | EF14: OFFWE | EG14: OFFWE | EH14: AL | EI14: AL | EJ14: AL | EK14: PH | EL14: AL | EM14: OFFWE | EN14: OFFWE | EO14: 08:00 - 17:00 | EP14: 08:00 - 17:00 | EQ14: 08:00 - 17:00 | ER14: 08:00 - 17:00 | ES14: 08:00 - 17:00 | ET14: OFFWE | EU14: OFFWE | EV14: PH | EW14: 08:00 - 17:00 | EX14: 08:00 - 17:00 | EY14: 08:00 - 17:00 | EZ14: 08:00 - 17:00 | FA14: OFFWE | FB14: OFFWE | FG14: AL | FH14: OFFWE | FI14: OFFWE | MX14: AL | MY14: AL | MZ14: AL | NA14: AL | NE14: AL | NF14: AL | NG14: AL | NH14: AL
A15: 7 | B15: 9074363 | C15: Danny Bendig | D15: Full Time | E15: Voice | F15: Voice | G15: Karlo Coric | H15: PH | I15: 07:00 - 11:00 15:30 - 19:00 | J15: OFFWE | K15: OFFWE | L15: HSL * | M15: SL | N15: SL | O15: SL | P15: SL | Q15: SL | R15: SL | S15: SL | T15: SL | U15: SL | V15: SL | W15: SL | X15: OFFWE | Y15: OFFWE | Z15: 07:00 - 11:00 15:30 - 19:00 | AA15: 07:00 - 11:00 15:30 - 19:00 | AB15: 07:00 - 11:00 15:30 - 19:00 | AC15: 07:00 - 11:00 15:30 - 19:00 | AD15: 07:00 - 11:00 15:30 - 19:00 | AE15: OFFWE | AF15: OFFWE | AG15: 07:00 - 11:00 15:30 - 19:00 | AH15: 07:00 - 11:00 15:30 - 19:00 | AI15: 07:00 - 11:00 15:30 - 19:00 | AJ15: 07:00 - 11:00 15:30 - 19:00 | AK15: 07:00 - 11:00 15:30 - 19:00 | AL15: OFFWE | AM15: OFFWE | AN15: 07:00 - 11:00 15:30 - 19:00 | AO15: 07:00 - 11:00 15:30 - 19:00 | AP15: 07:00 - 11:00 15:30 - 19:00 | AQ15: 07:00 - 11:00 15:30 - 19:00 | AR15: 07:00 - 11:00 15:30 - 19:00 | AS15: OFFWE | AT15: OFFWE | AU15: 07:00 - 11:00 15:30 - 19:00 | AV15: 07:00 - 11:00 15:30 - 19:00 | AW15: 07:00 - 11:00 15:30 - 19:00 | AX15: 07:00 - 11:00 15:30 - 19:00 | AY15: 07:00 - 11:00 15:30 - 19:00 | AZ15: OFFWE | BA15: OFFWE | BB15: 07:00 - 11:00 15:30 - 19:00 | BC15: 07:00 - 11:00 15:30 - 19:00 | BD15: 07:00 - 11:00 15:30 - 19:00 | BE15: 07:00 - 11:00 15:30 - 19:00 | BF15: 07:00 - 11:00 15:30 - 19:00 | BG15: OFFWE | BH15: OFFWE | BI15: AL | BJ15: AL | BK15: AL | BL15: AL | BM15: AL | BN15: OFFWE | BO15: OFFWE | BP15: 07:00 - 11:00 15:30 - 19:00 | BQ15: 07:00 - 11:00 15:30 - 19:00 | BR15: 07:00 - 11:00 15:30 - 19:00 | BS15: 07:00 - 11:00 15:30 - 19:00 | BT15: 07:00 - 11:00 15:30 - 19:00 | BU15: OFFWE | BV15: OFFWE | BW15: 07:00 - 11:00 15:30 - 19:00 | BX15: 07:00 - 11:00 15:30 - 19:00 | BY15: 07:00 - 11:00 15:30 - 19:00 | BZ15: 07:00 - 11:00 15:30 - 19:00 | CA15: 07:00 - 11:00 15:30 - 19:00 | CB15: OFFWE | CC15: OFFWE | CD15: 07:00 - 11:00 15:30 - 19:00 | CE15: 07:00 - 11:00 15:30 - 19:00 | CF15: 07:00 - 11:00 15:30 - 19:00 | CG15: 07:00 - 11:00 15:30 - 19:00 | CH15: 07:00 - 11:00 15:30 - 19:00 | CI15: OFFWE | CJ15: OFFWE | CK15: 07:00 - 11:00 15:30 - 19:00 | CL15: 07:00 - 11:00 15:30 - 19:00 | CM15: 07:00 - 11:00 15:30 - 19:00 | CN15: 07:00 - 11:00 15:30 - 19:00 | CO15: 07:00 - 11:00 15:30 - 19:00 | CP15: OFFWE | CQ15: OFFWE | CR15: 07:00 - 11:00 15:30 - 19:00 | CS15: 07:00 - 11:00 15:30 - 19:00 | CT15: 07:00 - 11:00 15:30 - 19:00 | CU15: 07:00 - 11:00 15:30 - 19:00 | CV15: PH | CW15: OFFWE | CX15: OFFWE | CY15: PH | CZ15: 07:00 - 11:00 15:30 - 19:00 | DA15: 07:00 - 11:00 15:30 - 19:00 | DB15: WIC 08:00 - 17:00 | DC15: WIC 08:00 - 17:00 | DD15: OFFWE | DE15: OFFWE | DF15: WIC 08:00 - 17:00 | DG15: WIC 08:00 - 17:00 | DH15: WIC 08:00 - 17:00 | DI15: WIC 08:00 - 17:00 | DJ15: WIC 08:00 - 17:00 | DK15: OFFWE | DL15: OFFWE | DM15: WIC 08:00 - 17:00 | DN15: WIC 08:00 - 17:00 | DO15: WIC 08:00 - 17:00 | DP15: WIC 08:00 - 17:00 | DQ15: WIC 08:00 - 17:00 | DR15: OFFWE | DS15: OFFWE | DT15: AL | DU15: AL | DV15: AL | DW15: AL | DX15: PH | DY15: OFFWE | DZ15: OFFWE | EA15: AL | EB15: AL | EC15: AL | ED15: AL | EE15: AL | EF15: OFFWE | EG15: OFFWE | EH15: WIC 08:00 - 17:00 | EI15: WIC 08:00 - 17:00 | EJ15: WIC 08:00 - 17:00 | EK15: PH | EL15: WIC 08:00 - 17:00 | EM15: OFFWE | EN15: OFFWE | EO15: WIC 08:00 - 17:00 | EP15: WIC 08:00 - 17:00 | EQ15: WIC 08:00 - 17:00 | ER15: WIC 08:00 - 17:00 | ES15: WIC 08:00 - 17:00 | ET15: OFFWE | EU15: OFFWE | EV15: PH | EW15: WIC 08:00 - 17:00 | EX15: WIC 08:00 - 17:01 | EY15: WIC 08:00 - 17:02 | EZ15: WIC 08:00 - 17:03 | FA15: OFFWE | FB15: OFFWE
A16: 8 | B16: 9074350 | C16: Baschir Mahrufi | D16: Full Time | E16: SSP | F16: Voice | G16: Tobias Rossberg | H16: PH | I16: 07:00 - 16:00 | J16: OFFWE | K16: OFFWE | L16: 07:00 - 16:00 | M16: 07:00 - 16:00 | N16: 07:00 - 16:00 | O16: 07:00 - 16:00 | P16: 07:00 - 16:00 | Q16: OFFWE | R16: OFFWE | S16: 07:00 - 16:00 | T16: 07:00 - 16:00 | U16: 07:00 - 16:00 | V16: 07:00 - 16:00 | W16: 07:00 - 16:00 | X16: OFFWE | Y16: OFFWE | Z16: 07:00 - 16:00 | AA16: 07:00 - 16:00 | AB16: 07:00 - 16:00 | AC16: 07:00 - 16:00 | AD16: 07:00 - 16:00 | AE16: OFFWE | AF16: OFFWE | AG16: 07:00 - 16:00 | AH16: 07:00 - 16:00 | AI16: 07:00 - 16:00 | AJ16: 07:00 - 16:00 | AK16: 07:00 - 16:00 | AL16: OFFWE | AM16: OFFWE | AN16: 07:00 - 16:00 | AO16: 07:00 - 16:00 | AP16: 07:00 - 16:00 | AQ16: 07:00 - 16:00 | AR16: 07:00 - 16:00 | AS16: OFFWE | AT16: OFFWE | AU16: 07:00 - 16:00 | AV16: AL | AW16: 07:00 - 16:00 | AX16: 07:00 - 16:00 | AY16: 07:00 - 16:00 | AZ16: OFFWE | BA16: OFFWE | BB16: 07:00 - 16:00 | BC16: 07:00 - 16:00 | BD16: 07:00 - 16:00 | BE16: 07:00 - 16:00 | BF16: 07:00 - 16:00 | BG16: OFFWE | BH16: OFFWE | BI16: 07:00 - 16:00 | BJ16: 07:00 - 16:00 | BK16: 07:00 - 16:00 | BL16: 07:00 - 16:00 | BM16: 07:00 - 16:00 | BN16: OFFWE | BO16: OFFWE | BP16: 07:00 - 16:00 | BQ16: 07:00 - 16:00 | BR16: 07:00 - 16:00 | BS16: 07:00 - 16:00 | BT16: 07:00 - 16:00 | BU16: OFFWE | BV16: OFFWE | BW16: 07:00 - 16:00 | BX16: 07:00 - 16:00 | BY16: 07:00 - 16:00 | BZ16: 07:00 - 16:00 | CA16: 07:00 - 16:00 | CB16: OFFWE | CC16: OFFWE | CD16: 07:00 - 16:00 | CE16: 07:00 - 16:00 | CF16: 07:00 - 16:00 | CG16: 07:00 - 16:00 | CH16: 07:00 - 16:00 | CI16: OFFWE | CJ16: OFFWE | CK16: 07:00 - 16:00 | CL16: 07:00 - 16:00 | CM16: 07:00 - 16:00 | CN16: 07:00 - 16:00 | CO16: 07:00 - 16:00 | CP16: OFFWE | CQ16: OFFWE | CR16: 07:00 - 16:00 | CS16: 07:00 - 16:00 | CT16: 07:00 - 16:00 | CU16: 07:00 - 16:00 | CV16: PH | CW16: OFFWE | CX16: OFFWE | CY16: PH | CZ16: 07:00 - 16:00 | DA16: 07:00 - 16:00 | DB16: 07:00 - 16:00 | DC16: 07:00 - 16:00 | DD16: OFFWE | DE16: OFFWE | DF16: 07:00 - 16:00 | DG16: 07:00 - 16:00 | DH16: 07:00 - 16:00 | DI16: 07:00 - 16:00 | DJ16: 07:00 - 16:00 | DK16: OFFWE | DL16: OFFWE | DM16: 07:00 - 16:00 | DN16: 07:00 - 16:00 | DO16: 07:00 - 16:00 | DP16: 07:00 - 16:00 | DQ16: 07:00 - 16:00 | DR16: OFFWE | DS16: OFFWE | DT16: 07:00 - 16:00 | DU16: 07:00 - 16:00 | DV16: 07:00 - 16:00 | DW16: 07:00 - 16:00 | DX16: PH | DY16: OFFWE | DZ16: OFFWE | EA16: 07:00 - 16:00 | EB16: 07:00 - 16:00 | EC16: 07:00 - 16:00 | ED16: 07:00 - 16:00 | EE16: 07:00 - 16:00 | EF16: OFFWE | EG16: OFFWE | EH16: 07:00 - 16:00 | EI16: 07:00 - 16:00 | EJ16: 07:00 - 16:00 | EK16: PH | EL16: 07:00 - 16:00 | EM16: OFFWE | EN16: OFFWE | EO16: AL | EP16: AL | EQ16: AL | ER16: AL | ES16: AL | ET16: OFFWE | EU16: OFFWE | EV16: PH | EW16: 08:00 - 17:00 | EX16: 08:00 - 17:00 | EY16: 08:00 - 17:00 | EZ16: 08:00 - 17:00 | FA16: OFFWE | FB16: OFFWE | GA16: AL | GB16: AL | GE16: AL | GF16: AL | GG16: AL | GH16: AL | GI16: AL | GZ16: AL | HA16: AL | HB16: AL | HC16: AL | HD16: AL | HG16: AL | HH16: AL | HI16: AL | HJ16: AL | HK16: AL
A17: 9 | B17: 9074364 | C17: Darjusch Dropczinsky | D17: Full Time | E17: Voice | F17: Voice | G17: Tobias Rossberg | H17: PH | I17: 08:00 - 17:00 | J17: OFFWE | K17: OFFWE | L17: 08:00 - 17:00 | M17: 08:00 - 17:00 | N17: 08:00 - 17:00 | O17: 08:00 - 17:00 | P17: * HSL | Q17: OFFWE | R17: OFFWE | S17: 08:00 - 17:00 | T17: 08:00 - 17:00 | U17: 08:00 - 17:00 | V17: 08:00 - 17:00 | W17: 08:00 - 17:00 | X17: OFFWE | Y17: OFFWE | Z17: 08:00 - 17:00 | AA17: 08:00 - 17:00 | AB17: 08:00 - 17:00 | AC17: 08:00 - 17:00 | AD17: 08:00 - 17:00 | AE17: OFFWE | AF17: OFFWE | AG17: 08:00 - 17:00 | AH17: 08:00 - 17:00 | AI17: 08:00 - 17:00 | AJ17: 08:00 - 17:00 | AK17: 08:00 - 17:00 | AL17: OFFWE | AM17: OFFWE | AN17: 08:00 - 17:00 | AO17: 08:00 - 17:00 | AP17: 08:00 - 17:00 | AQ17: 08:00 - 17:00 | AR17: 08:00 - 17:00 | AS17: OFFWE | AT17: OFFWE | AU17: SL | AV17: SL | AW17: SL | AX17: SL | AY17: SL | AZ17: OFFWE | BA17: OFFWE | BB17: 08:00 - 17:00 | BC17: SL | BD17: SL | BE17: SL | BF17: SL | BG17: OFFWE | BH17: OFFWE | BI17: 08:00 - 17:00 | BJ17: 08:00 - 17:00 | BK17: 08:00 - 17:00 | BL17: 08:00 - 17:00 | BM17: 08:00 - 17:00 | BN17: OFFWE | BO17: OFFWE | BP17: 08:00 - 17:00 | BQ17: 08:00 - 17:00 | BR17: 08:00 - 17:00 | BS17: 08:00 - 17:00 | BT17: 08:00 - 17:00 | BU17: OFFWE | BV17: OFFWE | BW17: 08:00 - 17:00 | BX17: SL | BY17: SL | BZ17: 08:00 - 17:00 | CA17: 08:00 - 17:00 | CB17: OFFWE | CC17: OFFWE | CD17: 08:00 - 17:00 | CE17: 08:00 - 17:00 | CF17: 08:00 - 17:00 | CG17: 08:00 - 17:00 | CH17: 08:00 - 17:00 | CI17: OFFWE | CJ17: OFFWE | CK17: 08:00 - 17:00 | CL17: 08:00 - 17:00 | CM17: 08:00 - 17:00 | CN17: 08:00 - 17:00 | CO17: 08:00 - 17:00 | CP17: OFFWE | CQ17: OFFWE | CR17: 08:00 - 17:00 | CS17: 08:00 - 17:00 | CT17: 08:00 - 17:00 | CU17: 08:00 - 17:00 | CV17: PH | CW17: OFFWE | CX17: OFFWE | CY17: PH | CZ17: 08:00 - 17:00 | DA17: SL | DB17: SL | DC17: SL | DD17: OFFWE | DE17: OFFWE | DF17: 08:00 - 17:00 | DG17: 08:00 - 17:00 | DH17: 08:00 - 17:00 | DI17: 08:00 - 17:00 | DJ17: 08:00 - 17:00 | DK17: OFFWE | DL17: OFFWE | DM17: 08:00 - 17:00 | DN17: 08:00 - 17:00 | DO17: 08:00 - 17:00 | DP17: 08:00 - 17:00 | DQ17: 08:00 - 17:00 | DR17: OFFWE | DS17: OFFWE | DT17: 08:00 - 17:00 | DU17: 08:00 - 17:00 | DV17: 08:00 - 17:00 | DW17: 08:00 - 17:00 | DX17: PH | DY17: OFFWE | DZ17: OFFWE | EA17: 08:00 - 17:00 | EB17: 08:00 - 17:00 | EC17: 08:00 - 17:00 | ED17: 08:00 - 17:00 | EE17: 08:00 - 17:00 | EF17: OFFWE | EG17: OFFWE | EH17: 08:00 - 17:00 | EI17: 08:00 - 17:00 | EJ17: 08:00 - 17:00 | EK17: PH | EL17: 08:00 - 17:00 | EM17: OFFWE | EN17: OFFWE | EO17: 08:00 - 17:00 | EP17: 08:00 - 17:00 | EQ17: 08:00 - 17:00 | ER17: 08:00 - 17:00 | ES17: 08:00 - 17:00 | ET17: OFFWE | EU17: OFFWE | EV17: 07:00 - 16:00 | EW17: 07:00 - 16:00 | EX17: 07:00 - 16:00 | EY17: 07:00 - 16:00 | EZ17: 07:00 - 16:00 | FA17: OFFWE | FB17: OFFWE | FC17: AL | FD17: AL | FE17: AL | FF17: LPH | FG17: AL | FH17: OFFWE | FI17: OFFWE | FJ17: AL | FK17: AL | FL17: AL | FM17: AL | FN17: AL | FO17: OFFWE | FP17: OFFWE | FQ17: AL | FR17: AL | FS17: AL | FT17: AL | FU17: AL
A18: 10 | B18: 9074373 | C18: Duc Quy Huynh | D18: Full Time | E18: Voice | F18: Voice | G18: Tobias Rossberg | H18: PH | I18: 07:00 - 16:00 | J18: OFFWE | K18: OFFWE | L18: SL | M18: SL | N18: SL | O18: 07:00 - 16:00 | P18: 07:00 - 16:00 | Q18: OFFWE | R18: OFFWE | S18: 07:00 - 16:00 | T18: 07:00 - 16:00 | U18: 07:00 - 16:00 | V18: 07:00 - 16:00 | W18: 07:00 - 16:00 | X18: OFFWE | Y18: OFFWE | Z18: 07:00 - 16:00 | AA18: 07:00 - 16:00 | AB18: 07:00 - 16:00 | AC18: 07:00 - 16:00 | AD18: 07:00 - 16:00 | AE18: OFFWE | AF18: OFFWE | AG18: 07:00 - 16:00 | AH18: 07:00 - 16:00 | AI18: 07:00 - 16:00 | AJ18: 07:00 - 16:00 | AK18: 07:00 - 16:00 | AL18: OFFWE | AM18: OFFWE | AN18: 07:00 - 16:00 | AO18: 07:00 - 16:00 | AP18: 07:00 - 16:00 | AQ18: 07:00 - 16:00 | AR18: 07:00 - 16:00 | AS18: OFFWE | AT18: OFFWE | AU18: 07:00 - 16:00 | AV18: 07:00 - 16:00 | AW18: 07:00 - 16:00 | AX18: 07:00 - 16:00 | AY18: 07:00 - 16:00 | AZ18: OFFWE | BA18: OFFWE | BB18: 07:00 - 16:00 | BC18: 07:00 - 16:00 | BD18: AL | BE18: 07:00 - 16:00 | BF18: 07:00 - 16:00 | BG18: OFFWE | BH18: OFFWE | BI18: SL | BJ18: SL | BK18: SL | BL18: 07:00 - 16:00 | BM18: 07:00 - 16:00 | BN18: OFFWE | BO18: OFFWE | BP18: 07:00 - 16:00 | BQ18: 07:00 - 16:00 | BR18: 07:00 - 16:00 | BS18: AL | BT18: 07:00 - 16:00 | BU18: OFFWE | BV18: OFFWE | BW18: 07:00 - 16:00 | BX18: 07:00 - 16:00 | BY18: 07:00 - 16:00 | BZ18: 07:00 - 16:00 | CA18: 07:00 - 16:00 | CB18: OFFWE | CC18: OFFWE | CD18: 07:00 - 16:00 | CE18: 07:00 - 16:00 | CF18: 07:00 - 16:00 | CG18: 07:00 - 16:00 | CH18: 07:00 - 16:00 | CI18: OFFWE | CJ18: OFFWE | CK18: SL | CL18: SL | CM18: 07:00 - 16:00 | CN18: 07:00 - 16:00 | CO18: 07:00 - 16:00 | CP18: OFFWE | CQ18: OFFWE | CR18: 07:00 - 16:00 | CS18: 07:00 - 16:00 | CT18: 07:00 - 16:00 | CU18: AL | CV18: PH | CW18: OFFWE | CX18: OFFWE | CY18: PH | CZ18: 07:00 - 16:00 | DA18: 07:00 - 16:00 | DB18: 07:00 - 16:00 | DC18: 07:00 - 16:00 | DD18: OFFWE | DE18: OFFWE | DF18: 07:00 - 16:00 | DG18: 07:00 - 16:00 | DH18: 07:00 - 16:00 | DI18: 07:00 - 16:00 | DJ18: 07:00 - 16:00 | DK18: OFFWE | DL18: OFFWE | DM18: 07:00 - 16:00 | DN18: 07:00 - 16:00 | DO18: 07:00 - 16:00 | DP18: 07:00 - 16:00 | DQ18: 07:00 - 16:00 | DR18: OFFWE | DS18: OFFWE | DT18: 07:00 - 16:00 | DU18: 07:00 - 16:00 | DV18: 07:00 - 16:00 | DW18: 07:00 - 16:00 | DX18: PH | DY18: OFFWE | DZ18: OFFWE | EA18: SL | EB18: SL | EC18: SL | ED18: 07:00 - 16:00 | EE18: 07:00 - 16:00 | EF18: OFFWE | EG18: OFFWE | EH18: 07:00 - 16:00 | EI18: 07:00 - 16:00 | EJ18: 07:00 - 16:00 | EK18: PH | EL18: 07:00 - 16:00 | EM18: OFFWE | EN18: OFFWE | EO18: 07:00 - 16:00 | EP18: 07:00 - 16:00 | EQ18: 07:00 - 16:00 | ER18: 07:00 - 16:00 | ES18: 07:00 - 16:00 | ET18: OFFWE | EU18: OFFWE | EV18: PH | EW18: 07:00 - 16:00 | EX18: 07:00 - 16:00 | EY18: 07:00 - 16:00 | EZ18: 07:00 - 16:00 | FA18: OFFWE | FB18: OFFWE | GP18: AL | GQ18: OFFWE | GR18: OFFWE | GS18: AL | GT18: AL | GU18: AL
A19: 11 | B19: 9074341 | C19: Anas Daba | D19: Full Time | E19: Voice | F19: Voice | G19: Delia Panaitescu | H19: PH | I19: 07:00 - 16:00 | J19: OFFWE | K19: OFFWE | L19: 07:00 - 16:00 | M19: 07:00 - 16:00 | N19: 07:00 - 16:00 | O19: 07:00 - 16:00 | P19: 07:00 - 16:00 | Q19: OFFWE | R19: OFFWE | S19: 22:00 - 07:00 | T19: 22:00 - 07:00 | U19: 22:00 - 07:00 | V19: 22:00 - 07:00 | W19: 22:00 - 07:00 | X19: OFFWE | Y19: OFFWE | Z19: 06:00 - 15:00 | AA19: 07:00 - 16:00 | AB19: 07:00 - 16:00 | AC19: 07:00 - 16:00 | AD19: 07:00 - 16:00 | AE19: OFFWE | AF19: OFFWE | AG19: 06:00 - 15:00 | AH19: OFF | AI19: 07:00 - 16:00 | AJ19: 07:00 - 16:00 | AK19: OFF | AL19: 22:00 - 07:00 | AM19: 22:00 - 07:00 | AN19: OFF | AO19: 06:00 - 15:00 | AP19: 06:00 - 15:00 | AQ19: 07:00 - 16:00 | AR19: 07:00 - 16:00 | AS19: OFFWE | AT19: OFFWE | AU19: 07:00 - 16:00 | AV19: OFF | AW19: OFF | AX19: 22:00 - 07:00 | AY19: 22:00 - 07:00 | AZ19: 22:00 - 07:00 | BA19: 22:00 - 07:00 | BB19: 22:00 - 07:00 | BC19: OFF | BD19: 07:00 - 16:00 | BE19: 07:00 - 16:00 | BF19: 07:00 - 16:00 | BG19: OFFWE | BH19: 07:00 - 16:00 | BI19: 07:00 - 16:00 | BJ19: OFF | BK19: 07:00 - 16:00 | BL19: 07:00 - 16:00 | BM19: 07:00 - 16:00 | BN19: OFFWE | BO19: OFFWE | BP19: 07:00 - 16:00 | BQ19: 07:00 - 16:00 | BR19: 07:00 - 16:00 | BS19: OFF | BT19: 07:00 - 16:00 | BU19: OFFWE | BV19: 22:00 - 07:00 | BW19: 22:00 - 07:00 | BX19: 22:00 - 07:00 | BY19: OFF | BZ19: 08:00 - 17:00 | CA19: 08:00 - 17:00 | CB19: OFFWE | CC19: 22:00 - 07:00 | CD19: OFF | CE19: 07:00 - 16:00 | CF19: SL | CG19: SL | CH19: SL | CI19: OFFWE | CJ19: OFFWE | CK19: 22:00 - 07:00 | CL19: 22:00 - 07:00 | CM19: 22:00 - 07:00 | CN19: 22:00 - 07:00 | CO19: 22:00 - 07:00 | CP19: OFFWE | CQ19: OFFWE | CR19: AL | CS19: AL | CT19: AL | CU19: AL | CV19: PH | CW19: OFFWE | CX19: OFFWE | CY19: PH | CZ19: AL | DA19: AL | DB19: AL | DC19: AL | DD19: OFFWE | DE19: OFFWE | DF19: 06:00 - 15:00 | DG19: OFF | DH19: OFF | DI19: 06:00 - 15:00 | DJ19: 06:00 - 15:00 | DK19: 22:00 - 07:00 | DL19: 22:00 - 07:00 | DM19: 22:00 - 07:00 | DN19: OFF | DO19: 07:00 - 16:00 | DP19: 07:00 - 16:00 | DQ19: 07:00 - 16:00 | DR19: OFFWE | DS19: OFFWE | DT19: 07:00 - 16:00 | DU19: 07:00 - 16:00 | DV19: 07:00 - 16:00 | DW19: 22:00 - 07:00 | DX19: PH | DY19: OFFWE | DZ19: OFFWE | EA19: 07:00 - 16:00 | EB19: 07:00 - 16:00 | EC19: OFF | ED19: OFF | EE19: 22:00 - 07:00 | EF19: 22:00 - 07:00 | EG19: 22:00 - 07:00 | EH19: 07:00 - 16:00 | EI19: 07:00 - 16:00 | EJ19: OFF | EK19: PH | EL19: 07:00 - 16:00 | EM19: OFFWE | EN19: 07:00 - 16:00 | EO19: 07:00 - 16:00 | EP19: 07:00 - 16:00 | EQ19: OFF | ER19: OFF | ES19: 22:00 - 07:00 | ET19: 22:00 - 07:00 | EU19: 22:00 - 07:00 | EV19: 22:00 - 07:00 | EW19: 22:00 - 07:00 | EX19: OFF | EY19: 07:00 - 16:00 | EZ19: 07:00 - 16:00 | FA19: OFFWE | FB19: OFFWE | FL19: 22:00 - 07:00 | FM19: 22:00 - 07:00 | FN19: 22:00 - 07:00 | FO19: 22:00 - 07:00 | FP19: 22:00 - 07:00 | GF19: 22:00 - 07:00 | GG19: 22:00 - 07:00 | GH19: 22:00 - 07:00 | GI19: 22:00 - 07:00 | GJ19: 22:00 - 07:00 | HN19: AL | HO19: AL | HP19: AL | HQ19: AL | HR19: AL | HS19: OFFWE | HT19: OFFWE | HU19: AL | HV19: AL | HW19: AL | HX19: AL | HY19: AL | HZ19: OFFWE | IA19: OFFWE | IB19: AL | IC19: AL | ID19: AL | IE19: AL | IF19: AL | IG19: OFFWE | IH19: OFFWE | II19: AL | IJ19: AL | IK19: AL | IL19: AL | IM19: AL | IN19: OFFWE | IO19: OFFWE
A20: 12 | B20: 9074381 | C20: Eva-Liane Schliwa | D20: Full Time | E20: Voice | F20: Voice | G20: Tobias Rossberg | H20: 07:00 - 16:00 | I20: CD | J20: OFFWE | K20: OFFWE | L20: SL | M20: SL | N20: SL | O20: SL | P20: SL | Q20: OFFWE | R20: OFFWE | S20: SL | T20: SL | U20: SL | V20: 07:00 - 16:00 | W20: SL | X20: OFFWE | Y20: OFFWE | Z20: 07:00 - 16:00 | AA20: SL | AB20: SL | AC20: 06:00 - 15:00 | AD20: CD | AE20: OFFWE | AF20: OFFWE | AG20: SL | AH20: SL | AI20: SL | AJ20: OFF | AK20: 06:00 - 15:00 | AL20: OFFWE | AM20: 07:00 - 16:00 | AN20: SL | AO20: 07:00 - 16:00 | AP20: 07:00 - 16:00 | AQ20: OFF | AR20: 06:00 - 15:00 | AS20: OFFWE | AT20: 07:00 - 16:00 | AU20: 07:00 - 16:00 | AV20: 06:00 - 15:00 | AW20: 07:00 - 16:00 | AX20: OFF | AY20: 07:00 - 16:00 | AZ20: OFFWE | BA20: OFFWE | BB20: SL | BC20: SL | BD20: 07:00 - 16:00 | BE20: 07:00 - 16:00 | BF20: 07:00 - 16:00 | BG20: OFFWE | BH20: OFFWE | BI20: 06:00 - 15:00 | BJ20: 06:00 - 15:00 | BK20: 06:00 - 15:00 | BL20: OFF | BM20: SL | BN20: 13:00 - 22:00 | BO20: OFFWE | BP20: 07:00 - 16:00 | BQ20: OFF | BR20: 07:00 - 16:00 | BS20: 07:00 - 16:00 | BT20: 07:00 - 16:00 | BU20: OFFWE | BV20: 13:00 - 22:00 | BW20: 13:00 - 22:00 | BX20: OFF | BY20: 06:00 - 15:00 | BZ20: 06:00 - 15:00 | CA20: 06:00 - 15:00 | CB20: OFFWE | CC20: 07:00 - 16:00 | CD20: 06:00 - 15:00 | CE20: 06:00 - 15:00 | CF20: 07:00 - 16:00 | CG20: 06:00 - 15:00 | CH20: OFF | CI20: OFFWE | CJ20: 13:00 - 22:00 | CK20: 10:00 - 19:00 | CL20: OFF | CM20: 07:00 - 16:00 | CN20: 06:00 - 15:00 | CO20: 07:00 - 16:00 | CP20: 13:00 - 22:00 | CQ20: OFFWE | CR20: 06:00 - 15:00 | CS20: OFF | CT20: 06:00 - 15:00 | CU20: 06:00 - 15:00 | CV20: PH | CW20: 13:00 - 22:00 | CX20: 13:00 - 22:00 | CY20: PH | CZ20: 06:00 - 15:00 | DA20: 06:00 - 15:00 | DB20: 06:00 - 15:00 | DC20: AL | DD20: OFFWE | DE20: 07:00 - 16:00 | DF20: 06:00 - 15:00 | DG20: 06:00 - 15:00 | DH20: 06:00 - 15:00 | DI20: 06:00 - 15:00 | DJ20: OFF | DK20: OFFWE | DL20: 07:00 - 16:00 | DM20: 07:00 - 16:00 | DN20: OFF | DO20: 06:00 - 15:00 | DP20: OFF | DQ20: 06:00 - 15:00 | DR20: 07:00 - 16:00 | DS20: OFFWE | DT20: 06:00 - 15:00 | DU20: OFF | DV20: 06:00 - 15:00 | DW20: HAL * | DX20: PH | DY20: 07:00 - 16:00 | DZ20: 07:00 - 16:00 | EA20: OFF | EB20: SL | EC20: SL | ED20: SL | EE20: SL | EF20: 13:00 - 22:00 | EG20: OFFWE | EH20: OFF | EI20: 06:00 - 15:00 | EJ20: 06:00 - 15:00 | EK20: 08:00 - 17:00 | EL20: 06:00 - 15:00 | EM20: 13:00 - 22:00 | EN20: 13:00 - 22:00 | EO20: OFF | EP20: 06:00 - 15:00 | EQ20: 06:00 - 15:00 | ER20: 06:00 - 15:00 | ES20: 06:00 - 15:00 | ET20: 13:00 - 22:00 | EU20: OFFWE | EV20: PH | EW20: 06:00 - 15:00 | EX20: 06:00 - 15:00 | EY20: 06:00 - 15:00 | EZ20: 06:00 - 15:00 | FA20: OFFWE | FB20: 07:00 - 16:00
A21: 13 | B21: 9078602 | C21: Tim Nguyen | D21: Full Time | E21: SSP | F21: Voice | G21: Delia Panaitescu | H21: PH | I21: 08:00 - 17:00 | J21: OFFWE | K21: OFFWE | L21: 08:00 - 17:00 | M21: 08:00 - 17:00 | N21: 08:00 - 17:00 | O21: 08:00 - 17:00 | P21: 08:00 - 17:00 | Q21: OFFWE | R21: OFFWE | S21: SL | T21: 08:00 - 17:00 | U21: 08:00 - 17:00 | V21: 08:00 - 17:00 | W21: 08:00 - 17:00 | X21: OFFWE | Y21: OFFWE | Z21: 08:00 - 17:00 | AA21: 08:00 - 17:00 | AB21: 08:00 - 17:00 | AC21: 08:00 - 17:00 | AD21: 08:00 - 17:00 | AE21: OFFWE | AF21: OFFWE | AG21: 08:00 - 17:00 | AH21: 08:00 - 17:00 | AI21: 08:00 - 17:00 | AJ21: 08:00 - 17:00 | AK21: 08:00 - 17:00 | AL21: OFFWE | AM21: OFFWE | AN21: 08:00 - 17:00 | AO21: 08:00 - 17:00 | AP21: 08:00 - 17:00 | AQ21: 08:00 - 17:00 | AR21: 08:00 - 17:00 | AS21: OFFWE | AT21: OFFWE | AU21: 08:00 - 17:00 | AV21: 08:00 - 17:00 | AW21: AL | AX21: 08:00 - 17:00 | AY21: 07:00 - 16:00 | AZ21: OFFWE | BA21: OFFWE | BB21: 08:00 - 17:00 | BC21: 07:00 - 16:00 | BD21: 08:00 - 17:00 | BE21: 07:00 - 16:00 | BF21: 08:00 - 17:00 | BG21: OFFWE | BH21: OFFWE | BI21: 08:00 - 17:00 | BJ21: 07:00 - 16:00 | BK21: 07:00 - 16:00 | BL21: 08:00 - 17:00 | BM21: 08:00 - 17:00 | BN21: OFFWE | BO21: OFFWE | BP21: 08:00 - 17:00 | BQ21: 07:00 - 16:00 | BR21: 08:00 - 17:00 | BS21: 08:00 - 17:00 | BT21: 08:00 - 17:00 | BU21: OFFWE | BV21: OFFWE | BW21: 08:00 - 17:00 | BX21: 07:00 - 16:00 | BY21: 07:00 - 16:00 | BZ21: AL | CA21: AL | CB21: OFFWE | CC21: OFFWE | CD21: 08:00 - 17:00 | CE21: 08:00 - 17:00 | CF21: 08:00 - 17:00 | CG21: 08:00 - 17:00 | CH21: 08:00 - 17:00 | CI21: OFFWE | CJ21: OFFWE | CK21: 08:00 - 17:00 | CL21: 08:00 - 17:00 | CM21: 08:00 - 17:00 | CN21: 08:00 - 17:00 | CO21: AL | CP21: OFFWE | CQ21: OFFWE | CR21: 08:00 - 17:00 | CS21: 08:00 - 17:00 | CT21: 08:00 - 17:00 | CU21: 08:00 - 17:00 | CV21: PH | CW21: OFFWE | CX21: OFFWE | CY21: PH | CZ21: AL | DA21: AL | DB21: AL | DC21: 07:00 - 16:00 | DD21: OFFWE | DE21: OFFWE | DF21: 08:00 - 17:00 | DG21: 08:00 - 17:00 | DH21: 08:00 - 17:00 | DI21: 08:00 - 17:00 | DJ21: 08:00 - 17:00 | DK21: OFFWE | DL21: OFFWE | DM21: 08:00 - 17:00 | DN21: 08:00 - 17:00 | DO21: 08:00 - 17:00 | DP21: 08:00 - 17:00 | DQ21: 08:00 - 17:00 | DR21: OFFWE | DS21: OFFWE | DT21: 08:00 - 17:00 | DU21: 08:00 - 17:00 | DV21: 08:00 - 17:00 | DW21: 08:00 - 17:00 | DX21: PH | DY21: OFFWE | DZ21: OFFWE | EA21: 08:00 - 17:00 | EB21: 08:00 - 17:00 | EC21: 08:00 - 17:00 | ED21: 08:00 - 17:00 | EE21: 08:00 - 17:00 | EF21: OFFWE | EG21: OFFWE | EH21: 08:00 - 17:00 | EI21: 08:00 - 17:00 | EJ21: 08:00 - 17:00 | EK21: PH | EL21: 08:00 - 17:00 | EM21: OFFWE | EN21: OFFWE | EO21: 08:00 - 17:00 | EP21: 08:00 - 17:00 | EQ21: 08:00 - 17:00 | ER21: 08:00 - 17:00 | ES21: 08:00 - 17:00 | ET21: OFFWE | EU21: OFFWE | EV21: PH | EW21: 08:00 - 17:00 | EX21: 08:00 - 17:00 | EY21: 08:00 - 17:00 | EZ21: 08:00 - 17:00 | FA21: OFFWE | FB21: OFFWE
A22: 14 | B22: 9085121 | C22: Walter Buxbaum | D22: Full Time | E22: Voice | F22: Voice | G22: Karlo Coric | H22: PH | I22: AL | J22: OFFWE | K22: OFFWE | L22: 08:00 - 17:00 | M22: 08:00 - 17:00 | N22: 08:00 - 17:00 | O22: 08:00 - 17:00 | P22: 08:00 - 17:00 | Q22: OFFWE | R22: OFFWE | S22: 08:00 - 17:00 | T22: 08:00 - 17:00 | U22: 08:00 - 17:00 | V22: 08:00 - 17:00 | W22: 08:00 - 17:00 | X22: OFFWE | Y22: OFFWE | Z22: 08:00 - 17:00 | AA22: 08:00 - 17:00 | AB22: 08:00 - 17:00 | AC22: 08:00 - 17:00 | AD22: 08:00 - 17:00 | AE22: OFFWE | AF22: OFFWE | AG22: 08:00 - 17:00 | AH22: 08:00 - 17:00 | AI22: 08:00 - 17:00 | AJ22: 08:00 - 17:00 | AK22: 08:00 - 17:00 | AL22: OFFWE | AM22: OFFWE | AN22: 08:00 - 17:00 | AO22: 08:00 - 17:00 | AP22: 08:00 - 17:00 | AQ22: 08:00 - 17:00 | AR22: 08:00 - 17:00 | AS22: OFFWE | AT22: OFFWE | AU22: 08:00 - 17:00 | AV22: 08:00 - 17:00 | AW22: 08:00 - 17:00 | AX22: 08:00 - 17:00 | AY22: AL | AZ22: OFFWE | BA22: OFFWE | BB22: 08:00 - 17:00 | BC22: 08:00 - 17:00 | BD22: 08:00 - 17:00 | BE22: 08:00 - 17:00 | BF22: 08:00 - 17:00 | BG22: OFFWE | BH22: OFFWE | BI22: 08:00 - 17:00 | BJ22: 08:00 - 17:00 | BK22: 08:00 - 17:00 | BL22: 08:00 - 17:00 | BM22: 08:00 - 17:00 | BN22: OFFWE | BO22: OFFWE | BP22: 08:00 - 17:00 | BQ22: 08:00 - 17:00 | BR22: 08:00 - 17:00 | BS22: 08:00 - 17:00 | BT22: 08:00 - 17:00 | BU22: OFFWE | BV22: OFFWE | BW22: 08:00 - 17:00 | BX22: 08:00 - 17:00 | BY22: 08:00 - 17:00 | BZ22: 08:00 - 17:00 | CA22: 08:00 - 17:00 | CB22: OFFWE | CC22: OFFWE | CD22: 08:00 - 17:00 | CE22: 08:00 - 17:00 | CF22: 08:00 - 17:00 | CG22: 08:00 - 17:00 | CH22: 08:00 - 17:00 | CI22: OFFWE | CJ22: OFFWE | CK22: 08:00 - 17:00 | CL22: 08:00 - 17:00 | CM22: 08:00 - 17:00 | CN22: 08:00 - 17:00 | CO22: 08:00 - 17:00 | CP22: OFFWE | CQ22: OFFWE | CR22: 08:00 - 17:00 | CS22: 07:00 - 16:00 | CT22: 08:00 - 17:00 | CU22: 08:00 - 17:00 | CV22: PH | CW22: OFFWE | CX22: OFFWE | CY22: PH | CZ22: 08:00 - 17:00 | DA22: 08:00 - 17:00 | DB22: 08:00 - 17:00 | DC22: 08:00 - 17:00 | DD22: OFFWE | DE22: OFFWE | DF22: 08:00 - 17:00 | DG22: 08:00 - 17:00 | DH22: 08:00 - 17:00 | DI22: 08:00 - 17:00 | DJ22: 08:00 - 17:00 | DK22: OFFWE | DL22: OFFWE | DM22: 08:00 - 17:00 | DN22: 08:00 - 17:00 | DO22: 08:00 - 17:00 | DP22: 08:00 - 17:00 | DQ22: 08:00 - 17:00 | DR22: OFFWE | DS22: OFFWE | DT22: 08:00 - 17:00 | DU22: 08:00 - 17:00 | DV22: 08:00 - 17:00 | DW22: 08:00 - 17:00 | DX22: PH | DY22: OFFWE | DZ22: OFFWE | EA22: 08:00 - 17:00 | EB22: 08:00 - 17:00 | EC22: 08:00 - 17:00 | ED22: 08:00 - 17:00 | EE22: 08:00 - 17:00 | EF22: OFFWE | EG22: OFFWE | EH22: 08:00 - 17:00 | EI22: 08:00 - 17:00 | EJ22: 08:00 - 17:00 | EK22: PH | EL22: 08:00 - 17:00 | EM22: OFFWE | EN22: OFFWE | EO22: 08:00 - 17:00 | EP22: 08:00 - 17:00 | EQ22: 08:00 - 17:00 | ER22: 08:00 - 17:00 | ES22: 08:00 - 17:00 | ET22: OFFWE | EU22: OFFWE | EV22: PH | EW22: 08:00 - 17:00 | EX22: 08:00 - 17:00 | EY22: 08:00 - 17:00 | EZ22: 08:00 - 17:00 | FA22: OFFWE | FB22: OFFWE | JY22: AL | JZ22: AL | KA22: AL | KB22: AL | KC22: AL | KF22: AL | KG22: AL | KH22: AL | KI22: AL | KJ22: AL | KM22: AL | KN22: AL | KO22: AL | KP22: AL | KQ22: AL
A23: 15 | B23: 9086658 | C23: Vincent Grunzel | D23: Full Time | E23: Voice | F23: Voice | G23: Tobias Rossberg | H23: PH | I23: SL | J23: OFFWE | K23: OFFWE | L23: 07:00 - 16:00 | M23: 07:00 - 16:00 | N23: 07:00 - 16:00 | O23: 07:00 - 16:00 | P23: 07:00 - 16:00 | Q23: OFFWE | R23: OFFWE | S23: 07:00 - 16:00 | T23: 07:00 - 16:00 | U23: 07:00 - 16:00 | V23: 07:00 - 16:00 | W23: 07:00 - 16:00 | X23: OFFWE | Y23: OFFWE | Z23: 07:00 - 16:00 | AA23: 07:00 - 16:00 | AB23: 07:00 - 16:00 | AC23: 07:00 - 16:00 | AD23: 07:00 - 16:00 | AE23: OFFWE | AF23: OFFWE | AG23: 07:00 - 16:00 | AH23: 07:00 - 16:00 | AI23: 07:00 - 16:00 | AJ23: 07:00 - 16:00 | AK23: 07:00 - 16:00 | AL23: OFFWE | AM23: OFFWE | AN23: 07:00 - 16:00 | AO23: 07:00 - 16:00 | AP23: 07:00 - 16:00 | AQ23: 07:00 - 16:00 | AR23: 07:00 - 16:00 | AS23: OFFWE | AT23: OFFWE | AU23: 07:00 - 16:00 | AV23: 07:00 - 16:00 | AW23: 07:00 - 16:00 | AX23: 07:00 - 16:00 | AY23: 07:00 - 16:00 | AZ23: OFFWE | BA23: OFFWE | BB23: 07:00 - 16:00 | BC23: 07:00 - 16:00 | BD23: 07:00 - 16:00 | BE23: 07:00 - 16:00 | BF23: 07:00 - 16:00 | BG23: OFFWE | BH23: OFFWE | BI23: 07:00 - 16:00 | BJ23: 07:00 - 16:00 | BK23: 07:00 - 16:00 | BL23: SL | BM23: SL | BN23: OFFWE | BO23: OFFWE | BP23: SL | BQ23: SL | BR23: SL | BS23: SL | BT23: SL | BU23: OFFWE | BV23: OFFWE | BW23: 07:00 - 16:00 | BX23: 07:00 - 16:00 | BY23: 07:00 - 16:00 | BZ23: 07:00 - 16:00 | CA23: 07:00 - 16:00 | CB23: OFFWE | CC23: OFFWE | CD23: 07:00 - 16:00 | CE23: 07:00 - 16:00 | CF23: 07:00 - 16:00 | CG23: 08:00 - 17:00 | CH23: 07:00 - 16:00 | CI23: OFFWE | CJ23: OFFWE | CK23: 07:00 - 16:00 | CL23: 07:00 - 16:00 | CM23: 07:00 - 16:00 | CN23: 07:00 - 16:00 | CO23: 07:00 - 16:00 | CP23: OFFWE | CQ23: OFFWE | CR23: 07:00 - 16:00 | CS23: 07:00 - 16:00 | CT23: 07:00 - 16:00 | CU23: 07:00 - 16:00 | CV23: PH | CW23: OFFWE | CX23: OFFWE | CY23: PH | CZ23: AL | DA23: AL | DB23: AL | DC23: AL | DD23: OFFWE | DE23: OFFWE | DF23: 07:00 - 16:00 | DG23: 07:00 - 16:00 | DH23: 07:00 - 16:00 | DI23: 07:00 - 16:00 | DJ23: 07:00 - 16:00 | DK23: OFFWE | DL23: OFFWE | DM23: 07:00 - 16:00 | DN23: 07:00 - 16:00 | DO23: 07:00 - 16:00 | DP23: SL | DQ23: SL | DR23: OFFWE | DS23: OFFWE | DT23: AL | DU23: AL | DV23: AL | DW23: AL | DX23: PH | DY23: OFFWE | DZ23: OFFWE | EA23: 07:00 - 16:00 | EB23: 07:00 - 16:00 | EC23: 07:00 - 16:00 | ED23: 07:00 - 16:00 | EE23: 07:00 - 16:00 | EF23: OFFWE | EG23: OFFWE | EH23: AL | EI23: AL | EJ23: AL | EK23: PH | EL23: AL | EM23: OFFWE | EN23: OFFWE | EO23: 07:00 - 16:00 | EP23: 07:00 - 16:00 | EQ23: 07:00 - 16:00 | ER23: 07:00 - 16:00 | ES23: 07:00 - 16:00 | ET23: OFFWE | EU23: OFFWE | EV23: PH | EW23: AL | EX23: AL | EY23: AL | EZ23: AL | FA23: OFFWE | FB23: OFFWE
A24: 16 | B24: 9087657 | C24: Meik Schülgen | D24: Full Time | E24: Voice | F24: Voice | G24: Tobias Rossberg | H24: PH | I24: AL | J24: OFFWE | K24: OFFWE | L24: 07:00 - 16:00 | M24: 07:00 - 16:00 | N24: 07:00 - 16:00 | O24: 07:00 - 16:00 | P24: 08:00 - 17:00 | Q24: OFFWE | R24: OFFWE | S24: 07:00 - 16:00 | T24: 07:00 - 16:00 | U24: 07:00 - 16:00 | V24: 07:00 - 16:00 | W24: 07:00 - 16:00 | X24: OFFWE | Y24: OFFWE | Z24: 07:00 - 16:00 | AA24: 07:00 - 16:00 | AB24: 07:00 - 16:00 | AC24: 07:00 - 16:00 | AD24: 07:00 - 16:00 | AE24: OFFWE | AF24: OFFWE | AG24: 07:00 - 16:00 | AH24: 07:00 - 16:00 | AI24: 07:00 - 16:00 | AJ24: 07:00 - 16:00 | AK24: 07:00 - 16:00 | AL24: OFFWE | AM24: OFFWE | AN24: 07:00 - 16:00 | AO24: 07:00 - 16:00 | AP24: 07:00 - 16:00 | AQ24: 07:00 - 16:00 | AR24: 07:00 - 16:00 | AS24: OFFWE | AT24: OFFWE | AU24: 07:00 - 16:00 | AV24: 07:00 - 16:00 | AW24: 07:00 - 16:00 | AX24: 07:00 - 16:00 | AY24: 07:00 - 16:00 | AZ24: OFFWE | BA24: OFFWE | BB24: AL | BC24: 07:00 - 16:00 | BD24: 07:00 - 16:00 | BE24: 07:00 - 16:00 | BF24: 07:00 - 16:00 | BG24: OFFWE | BH24: OFFWE | BI24: SL | BJ24: SL | BK24: SL | BL24: SL | BM24: SL | BN24: OFFWE | BO24: OFFWE | BP24: 07:00 - 16:00 | BQ24: 07:00 - 16:00 | BR24: 07:00 - 16:00 | BS24: 07:00 - 16:00 | BT24: 07:00 - 16:00 | BU24: OFFWE | BV24: OFFWE | BW24: 07:00 - 16:00 | BX24: 07:00 - 16:00 | BY24: 07:00 - 16:00 | BZ24: 07:00 - 16:00 | CA24: 07:00 - 16:00 | CB24: OFFWE | CC24: OFFWE | CD24: 07:00 - 16:00 | CE24: 07:00 - 16:00 | CF24: 07:00 - 16:00 | CG24: 07:00 - 16:00 | CH24: 07:00 - 16:00 | CI24: OFFWE | CJ24: OFFWE | CK24: 07:00 - 16:00 | CL24: 07:00 - 16:00 | CM24: 07:00 - 16:00 | CN24: 07:00 - 16:00 | CO24: 07:00 - 16:00 | CP24: OFFWE | CQ24: OFFWE | CR24: AL | CS24: AL | CT24: AL | CU24: AL | CV24: PH | CW24: OFFWE | CX24: OFFWE | CY24: PH | CZ24: 07:00 - 16:00 | DA24: 07:00 - 16:00 | DB24: 07:00 - 16:00 | DC24: 07:00 - 16:00 | DD24: OFFWE | DE24: OFFWE | DF24: 07:00 - 16:00 | DG24: 07:00 - 16:00 | DH24: 07:00 - 16:00 | DI24: 07:00 - 16:00 | DJ24: 07:00 - 16:00 | DK24: OFFWE | DL24: OFFWE | DM24: 07:00 - 16:00 | DN24: 07:00 - 16:00 | DO24: 07:00 - 16:00 | DP24: 07:00 - 16:00 | DQ24: 07:00 - 16:00 | DR24: OFFWE | DS24: OFFWE | DT24: 07:00 - 16:00 | DU24: 07:00 - 16:00 | DV24: 07:00 - 16:00 | DW24: 07:00 - 16:00 | DX24: PH | DY24: OFFWE | DZ24: OFFWE | EA24: 07:00 - 16:00 | EB24: 07:00 - 16:00 | EC24: 07:00 - 16:00 | ED24: 07:00 - 16:00 | EE24: 07:00 - 16:00 | EF24: OFFWE | EG24: OFFWE | EH24: 07:00 - 16:00 | EI24: 07:00 - 16:00 | EJ24: 07:00 - 16:00 | EK24: PH | EL24: AL | EM24: OFFWE | EN24: OFFWE | EO24: 07:00 - 16:00 | EP24: 07:00 - 16:00 | EQ24: 07:00 - 16:00 | ER24: 07:00 - 16:00 | ES24: 07:00 - 16:00 | ET24: OFFWE | EU24: OFFWE | EV24: PH | EW24: 07:00 - 16:00 | EX24: 07:00 - 16:00 | EY24: 07:00 - 16:00 | EZ24: 07:00 - 16:00 | FA24: OFFWE | FB24: OFFWE | FG24: AL | GW24: AL | GZ24: AL | HA24: AL | HB24: AL | HC24: AL | HD24: AL | HG24: AL | HH24: AL | HI24: AL | HJ24: AL | HK24: AL
